main.py:10 #INFO     [2025-03-11 13:33:02,832] - config.logger - Starting bot
client.py:15 #INFO     [2025-03-11 13:33:03,403] - config.logger - Successfully connected to the SQLite database!
dispatcher.py:527 #INFO     [2025-03-11 13:33:03,565] - aiogram.dispatcher - Start polling
dispatcher.py:341 #INFO     [2025-03-11 13:33:03,716] - aiogram.dispatcher - Run polling for bot @free_listening_marathon_bot id=7531140107 - 'FREE LISTENING MARATHON'
subscription.py:30 #INFO     [2025-03-11 13:33:10,688] - config.logger - USER: 1856563190, Azizbek Qodirov
dispatcher.py:172 #INFO     [2025-03-11 13:33:11,195] - aiogram.event - Update id=475224172 is not handled. Duration 517 ms by bot id=7531140107
dispatcher.py:315 #ERROR    [2025-03-11 13:33:11,228] - aiogram.event - Cause exception while process update id=475224172 by bot id=7531140107
TelegramBadRequest: Telegram server says - Bad Request: wrong file identifier/HTTP URL specified
Traceback (most recent call last):
  File "/home/ubuntu/projects/isaev/venv/lib/python3.12/site-packages/aiogram/dispatcher/dispatcher.py", line 309, in _process_update
    response = await self.feed_update(bot, update, **kwargs)
               ^^^^^^^^^^^^^^^^^^^^^^^^^^^^^^^^^^^^^^^^^^^^^
  File "/home/ubuntu/projects/isaev/venv/lib/python3.12/site-packages/aiogram/dispatcher/dispatcher.py", line 158, in feed_update
    response = await self.update.wrap_outer_middleware(
               ^^^^^^^^^^^^^^^^^^^^^^^^^^^^^^^^^^^^^^^^
  File "/home/ubuntu/projects/isaev/venv/lib/python3.12/site-packages/aiogram/dispatcher/middlewares/error.py", line 25, in __call__
    return await handler(event, data)
           ^^^^^^^^^^^^^^^^^^^^^^^^^^
  File "/home/ubuntu/projects/isaev/venv/lib/python3.12/site-packages/aiogram/dispatcher/middlewares/user_context.py", line 56, in __call__
    return await handler(event, data)
           ^^^^^^^^^^^^^^^^^^^^^^^^^^
  File "/home/ubuntu/projects/isaev/venv/lib/python3.12/site-packages/aiogram/fsm/middleware.py", line 42, in __call__
    return await handler(event, data)
           ^^^^^^^^^^^^^^^^^^^^^^^^^^
  File "/home/ubuntu/projects/isaev/venv/lib/python3.12/site-packages/aiogram/dispatcher/event/telegram.py", line 121, in trigger
    return await wrapped_inner(event, kwargs)
           ^^^^^^^^^^^^^^^^^^^^^^^^^^^^^^^^^^
  File "/home/ubuntu/projects/isaev/venv/lib/python3.12/site-packages/aiogram/dispatcher/event/handler.py", line 43, in call
    return await wrapped()
           ^^^^^^^^^^^^^^^
  File "/home/ubuntu/projects/isaev/venv/lib/python3.12/site-packages/aiogram/dispatcher/dispatcher.py", line 276, in _listen_update
    return await self.propagate_event(update_type=update_type, event=event, **kwargs)
           ^^^^^^^^^^^^^^^^^^^^^^^^^^^^^^^^^^^^^^^^^^^^^^^^^^^^^^^^^^^^^^^^^^^^^^^^^^
  File "/home/ubuntu/projects/isaev/venv/lib/python3.12/site-packages/aiogram/dispatcher/router.py", line 146, in propagate_event
    return await observer.wrap_outer_middleware(_wrapped, event=event, data=kwargs)
           ^^^^^^^^^^^^^^^^^^^^^^^^^^^^^^^^^^^^^^^^^^^^^^^^^^^^^^^^^^^^^^^^^^^^^^^^
  File "/home/ubuntu/projects/isaev/venv/lib/python3.12/site-packages/aiogram/dispatcher/router.py", line 141, in _wrapped
    return await self._propagate_event(
           ^^^^^^^^^^^^^^^^^^^^^^^^^^^^
  File "/home/ubuntu/projects/isaev/venv/lib/python3.12/site-packages/aiogram/dispatcher/router.py", line 174, in _propagate_event
    response = await router.propagate_event(update_type=update_type, event=event, **kwargs)
               ^^^^^^^^^^^^^^^^^^^^^^^^^^^^^^^^^^^^^^^^^^^^^^^^^^^^^^^^^^^^^^^^^^^^^^^^^^^^
  File "/home/ubuntu/projects/isaev/venv/lib/python3.12/site-packages/aiogram/dispatcher/router.py", line 146, in propagate_event
    return await observer.wrap_outer_middleware(_wrapped, event=event, data=kwargs)
           ^^^^^^^^^^^^^^^^^^^^^^^^^^^^^^^^^^^^^^^^^^^^^^^^^^^^^^^^^^^^^^^^^^^^^^^^
  File "/home/ubuntu/projects/isaev/venv/lib/python3.12/site-packages/aiogram/dispatcher/router.py", line 141, in _wrapped
    return await self._propagate_event(
           ^^^^^^^^^^^^^^^^^^^^^^^^^^^^
  File "/home/ubuntu/projects/isaev/venv/lib/python3.12/site-packages/aiogram/dispatcher/router.py", line 166, in _propagate_event
    response = await observer.trigger(event, **kwargs)
               ^^^^^^^^^^^^^^^^^^^^^^^^^^^^^^^^^^^^^^^
  File "/home/ubuntu/projects/isaev/venv/lib/python3.12/site-packages/aiogram/dispatcher/event/telegram.py", line 121, in trigger
    return await wrapped_inner(event, kwargs)
           ^^^^^^^^^^^^^^^^^^^^^^^^^^^^^^^^^^
  File "/home/ubuntu/projects/isaev/src/middleware/subscription.py", line 93, in __call__
    return await handler(event, data)
           ^^^^^^^^^^^^^^^^^^^^^^^^^^
  File "/home/ubuntu/projects/isaev/venv/lib/python3.12/site-packages/aiogram/dispatcher/event/handler.py", line 43, in call
    return await wrapped()
           ^^^^^^^^^^^^^^^
  File "/home/ubuntu/projects/isaev/src/handlers/start.py", line 59, in bot_start
    await message.answer_photo(photo=msg.photo_id, caption=msg.text_1, parse_mode=ParseMode.HTML)
  File "/home/ubuntu/projects/isaev/venv/lib/python3.12/site-packages/aiogram/methods/base.py", line 84, in emit
    return await bot(self)
           ^^^^^^^^^^^^^^^
  File "/home/ubuntu/projects/isaev/venv/lib/python3.12/site-packages/aiogram/client/bot.py", line 494, in __call__
    return await self.session(self, method, timeout=request_timeout)
           ^^^^^^^^^^^^^^^^^^^^^^^^^^^^^^^^^^^^^^^^^^^^^^^^^^^^^^^^^
  File "/home/ubuntu/projects/isaev/venv/lib/python3.12/site-packages/aiogram/client/session/base.py", line 254, in __call__
    return cast(TelegramType, await middleware(bot, method))
                              ^^^^^^^^^^^^^^^^^^^^^^^^^^^^^
  File "/home/ubuntu/projects/isaev/venv/lib/python3.12/site-packages/aiogram/client/session/aiohttp.py", line 189, in make_request
    response = self.check_response(
               ^^^^^^^^^^^^^^^^^^^^
  File "/home/ubuntu/projects/isaev/venv/lib/python3.12/site-packages/aiogram/client/session/base.py", line 120, in check_response
    raise TelegramBadRequest(method=method, message=description)
aiogram.exceptions.TelegramBadRequest: Telegram server says - Bad Request: wrong file identifier/HTTP URL specified
dispatcher.py:455 #WARNING  [2025-03-11 13:33:21,772] - aiogram.dispatcher - Received SIGINT signal
dispatcher.py:359 #INFO     [2025-03-11 13:33:21,773] - aiogram.dispatcher - Polling stopped for bot @free_listening_marathon_bot id=7531140107 - 'FREE LISTENING MARATHON'
dispatcher.py:554 #INFO     [2025-03-11 13:33:21,773] - aiogram.dispatcher - Polling stopped
client.py:22 #INFO     [2025-03-11 13:33:22,028] - config.logger - Connection to SQLite closed!
main.py:10 #INFO     [2025-03-11 13:36:25,958] - config.logger - Starting bot
client.py:15 #INFO     [2025-03-11 13:36:27,240] - config.logger - Successfully connected to the SQLite database!
client.py:45 #ERROR    [2025-03-11 13:36:27,242] - config.logger - SQLite error: table users already exists
dispatcher.py:527 #INFO     [2025-03-11 13:36:27,344] - aiogram.dispatcher - Start polling
dispatcher.py:341 #INFO     [2025-03-11 13:36:27,476] - aiogram.dispatcher - Run polling for bot @free_listening_marathon_bot id=7531140107 - 'FREE LISTENING MARATHON'
subscription.py:30 #INFO     [2025-03-11 13:36:34,988] - config.logger - USER: 1856563190, Azizbek Qodirov
dispatcher.py:172 #INFO     [2025-03-11 13:36:35,548] - aiogram.event - Update id=475224173 is not handled. Duration 622 ms by bot id=7531140107
dispatcher.py:315 #ERROR    [2025-03-11 13:36:35,549] - aiogram.event - Cause exception while process update id=475224173 by bot id=7531140107
TelegramBadRequest: Telegram server says - Bad Request: wrong file identifier/HTTP URL specified
Traceback (most recent call last):
  File "/usr/local/lib/python3.12/site-packages/aiogram/dispatcher/dispatcher.py", line 309, in _process_update
    response = await self.feed_update(bot, update, **kwargs)
               ^^^^^^^^^^^^^^^^^^^^^^^^^^^^^^^^^^^^^^^^^^^^^
  File "/usr/local/lib/python3.12/site-packages/aiogram/dispatcher/dispatcher.py", line 158, in feed_update
    response = await self.update.wrap_outer_middleware(
               ^^^^^^^^^^^^^^^^^^^^^^^^^^^^^^^^^^^^^^^^
  File "/usr/local/lib/python3.12/site-packages/aiogram/dispatcher/middlewares/error.py", line 25, in __call__
    return await handler(event, data)
           ^^^^^^^^^^^^^^^^^^^^^^^^^^
  File "/usr/local/lib/python3.12/site-packages/aiogram/dispatcher/middlewares/user_context.py", line 56, in __call__
    return await handler(event, data)
           ^^^^^^^^^^^^^^^^^^^^^^^^^^
  File "/usr/local/lib/python3.12/site-packages/aiogram/fsm/middleware.py", line 42, in __call__
    return await handler(event, data)
           ^^^^^^^^^^^^^^^^^^^^^^^^^^
  File "/usr/local/lib/python3.12/site-packages/aiogram/dispatcher/event/telegram.py", line 121, in trigger
    return await wrapped_inner(event, kwargs)
           ^^^^^^^^^^^^^^^^^^^^^^^^^^^^^^^^^^
  File "/usr/local/lib/python3.12/site-packages/aiogram/dispatcher/event/handler.py", line 43, in call
    return await wrapped()
           ^^^^^^^^^^^^^^^
  File "/usr/local/lib/python3.12/site-packages/aiogram/dispatcher/dispatcher.py", line 276, in _listen_update
    return await self.propagate_event(update_type=update_type, event=event, **kwargs)
           ^^^^^^^^^^^^^^^^^^^^^^^^^^^^^^^^^^^^^^^^^^^^^^^^^^^^^^^^^^^^^^^^^^^^^^^^^^
  File "/usr/local/lib/python3.12/site-packages/aiogram/dispatcher/router.py", line 146, in propagate_event
    return await observer.wrap_outer_middleware(_wrapped, event=event, data=kwargs)
           ^^^^^^^^^^^^^^^^^^^^^^^^^^^^^^^^^^^^^^^^^^^^^^^^^^^^^^^^^^^^^^^^^^^^^^^^
  File "/usr/local/lib/python3.12/site-packages/aiogram/dispatcher/router.py", line 141, in _wrapped
    return await self._propagate_event(
           ^^^^^^^^^^^^^^^^^^^^^^^^^^^^
  File "/usr/local/lib/python3.12/site-packages/aiogram/dispatcher/router.py", line 174, in _propagate_event
    response = await router.propagate_event(update_type=update_type, event=event, **kwargs)
               ^^^^^^^^^^^^^^^^^^^^^^^^^^^^^^^^^^^^^^^^^^^^^^^^^^^^^^^^^^^^^^^^^^^^^^^^^^^^
  File "/usr/local/lib/python3.12/site-packages/aiogram/dispatcher/router.py", line 146, in propagate_event
    return await observer.wrap_outer_middleware(_wrapped, event=event, data=kwargs)
           ^^^^^^^^^^^^^^^^^^^^^^^^^^^^^^^^^^^^^^^^^^^^^^^^^^^^^^^^^^^^^^^^^^^^^^^^
  File "/usr/local/lib/python3.12/site-packages/aiogram/dispatcher/router.py", line 141, in _wrapped
    return await self._propagate_event(
           ^^^^^^^^^^^^^^^^^^^^^^^^^^^^
  File "/usr/local/lib/python3.12/site-packages/aiogram/dispatcher/router.py", line 166, in _propagate_event
    response = await observer.trigger(event, **kwargs)
               ^^^^^^^^^^^^^^^^^^^^^^^^^^^^^^^^^^^^^^^
  File "/usr/local/lib/python3.12/site-packages/aiogram/dispatcher/event/telegram.py", line 121, in trigger
    return await wrapped_inner(event, kwargs)
           ^^^^^^^^^^^^^^^^^^^^^^^^^^^^^^^^^^
  File "/app/src/middleware/subscription.py", line 93, in __call__
    return await handler(event, data)
           ^^^^^^^^^^^^^^^^^^^^^^^^^^
  File "/usr/local/lib/python3.12/site-packages/aiogram/dispatcher/event/handler.py", line 43, in call
    return await wrapped()
           ^^^^^^^^^^^^^^^
  File "/app/src/handlers/start.py", line 59, in bot_start
    await message.answer_photo(photo=msg.photo_id, caption=msg.text_1, parse_mode=ParseMode.HTML)
  File "/usr/local/lib/python3.12/site-packages/aiogram/methods/base.py", line 84, in emit
    return await bot(self)
           ^^^^^^^^^^^^^^^
  File "/usr/local/lib/python3.12/site-packages/aiogram/client/bot.py", line 494, in __call__
    return await self.session(self, method, timeout=request_timeout)
           ^^^^^^^^^^^^^^^^^^^^^^^^^^^^^^^^^^^^^^^^^^^^^^^^^^^^^^^^^
  File "/usr/local/lib/python3.12/site-packages/aiogram/client/session/base.py", line 254, in __call__
    return cast(TelegramType, await middleware(bot, method))
                              ^^^^^^^^^^^^^^^^^^^^^^^^^^^^^
  File "/usr/local/lib/python3.12/site-packages/aiogram/client/session/aiohttp.py", line 189, in make_request
    response = self.check_response(
               ^^^^^^^^^^^^^^^^^^^^
  File "/usr/local/lib/python3.12/site-packages/aiogram/client/session/base.py", line 120, in check_response
    raise TelegramBadRequest(method=method, message=description)
aiogram.exceptions.TelegramBadRequest: Telegram server says - Bad Request: wrong file identifier/HTTP URL specified
subscription.py:30 #INFO     [2025-03-11 13:38:16,934] - config.logger - USER: 1856563190, Azizbek Qodirov
subscription.py:91 #CRITICAL [2025-03-11 13:38:16,934] - config.logger - Error in SubscriptionMiddleware: 'NoneType' object has no attribute 'startswith'
start.py:65 #INFO     [2025-03-11 13:38:16,934] - config.logger - Photo ID: AgACAgIAAxkBAAEBE2xn0DzI8F9TIAnEXHkRW1VgVd8j1gACbPAxG4aNgEq8ODVc02JZugEAAwIAA3kAAzYE
dispatcher.py:172 #INFO     [2025-03-11 13:38:16,934] - aiogram.event - Update id=475224174 is handled. Duration 1 ms by bot id=7531140107
dispatcher.py:455 #WARNING  [2025-03-11 13:40:35,323] - aiogram.dispatcher - Received SIGTERM signal
dispatcher.py:359 #INFO     [2025-03-11 13:40:35,324] - aiogram.dispatcher - Polling stopped for bot @free_listening_marathon_bot id=7531140107 - 'FREE LISTENING MARATHON'
dispatcher.py:554 #INFO     [2025-03-11 13:40:35,324] - aiogram.dispatcher - Polling stopped
client.py:22 #INFO     [2025-03-11 13:40:35,628] - config.logger - Connection to SQLite closed!
main.py:10 #INFO     [2025-03-11 13:42:02,227] - config.logger - Starting bot
client.py:15 #INFO     [2025-03-11 13:42:03,570] - config.logger - Successfully connected to the SQLite database!
client.py:45 #ERROR    [2025-03-11 13:42:03,581] - config.logger - SQLite error: table users already exists
dispatcher.py:527 #INFO     [2025-03-11 13:42:03,708] - aiogram.dispatcher - Start polling
dispatcher.py:341 #INFO     [2025-03-11 13:42:03,807] - aiogram.dispatcher - Run polling for bot @free_listening_marathon_bot id=7531140107 - 'FREE LISTENING MARATHON'
subscription.py:30 #INFO     [2025-03-11 13:42:20,672] - config.logger - USER: 1856563190, Azizbek Qodirov
subscription.py:91 #CRITICAL [2025-03-11 13:42:20,672] - config.logger - Error in SubscriptionMiddleware: 'NoneType' object has no attribute 'startswith'
start.py:65 #INFO     [2025-03-11 13:42:20,672] - config.logger - Photo ID: AgACAgIAAxkBAAEBE2xn0DzI8F9TIAnEXHkRW1VgVd8j1gACbPAxG4aNgEq8ODVc02JZugEAAwIAA3kAAzYE
dispatcher.py:172 #INFO     [2025-03-11 13:42:20,672] - aiogram.event - Update id=475224175 is handled. Duration 2 ms by bot id=7531140107
dispatcher.py:455 #WARNING  [2025-03-11 13:42:27,229] - aiogram.dispatcher - Received SIGTERM signal
dispatcher.py:359 #INFO     [2025-03-11 13:42:27,230] - aiogram.dispatcher - Polling stopped for bot @free_listening_marathon_bot id=7531140107 - 'FREE LISTENING MARATHON'
dispatcher.py:554 #INFO     [2025-03-11 13:42:27,232] - aiogram.dispatcher - Polling stopped
client.py:22 #INFO     [2025-03-11 13:42:27,484] - config.logger - Connection to SQLite closed!
main.py:10 #INFO     [2025-03-11 13:45:21,397] - config.logger - Starting bot
client.py:15 #INFO     [2025-03-11 13:45:22,699] - config.logger - Successfully connected to the SQLite database!
client.py:45 #ERROR    [2025-03-11 13:45:22,750] - config.logger - SQLite error: table users already exists
dispatcher.py:527 #INFO     [2025-03-11 13:45:22,912] - aiogram.dispatcher - Start polling
dispatcher.py:341 #INFO     [2025-03-11 13:45:23,021] - aiogram.dispatcher - Run polling for bot @free_listening_marathon_bot id=7531140107 - 'FREE LISTENING MARATHON'
subscription.py:30 #INFO     [2025-03-11 13:45:33,235] - config.logger - USER: 1856563190, Azizbek Qodirov
dispatcher.py:172 #INFO     [2025-03-11 13:45:33,869] - aiogram.event - Update id=475224176 is handled. Duration 635 ms by bot id=7531140107
subscription.py:30 #INFO     [2025-03-11 13:45:40,760] - config.logger - USER: 1856563190, Azizbek Qodirov
dispatcher.py:172 #INFO     [2025-03-11 13:45:41,069] - aiogram.event - Update id=475224177 is handled. Duration 319 ms by bot id=7531140107
subscription.py:30 #INFO     [2025-03-11 13:45:42,518] - config.logger - USER: 1856563190, Azizbek Qodirov
dispatcher.py:172 #INFO     [2025-03-11 13:45:42,857] - aiogram.event - Update id=475224178 is handled. Duration 347 ms by bot id=7531140107
dispatcher.py:455 #WARNING  [2025-03-11 13:45:55,957] - aiogram.dispatcher - Received SIGTERM signal
dispatcher.py:359 #INFO     [2025-03-11 13:45:55,958] - aiogram.dispatcher - Polling stopped for bot @free_listening_marathon_bot id=7531140107 - 'FREE LISTENING MARATHON'
dispatcher.py:554 #INFO     [2025-03-11 13:45:55,958] - aiogram.dispatcher - Polling stopped
client.py:22 #INFO     [2025-03-11 13:45:56,268] - config.logger - Connection to SQLite closed!
main.py:10 #INFO     [2025-04-16 10:37:06,336] - config.logger - Starting bot
client.py:15 #INFO     [2025-04-16 10:37:12,076] - config.logger - Successfully connected to the SQLite database!
client.py:45 #ERROR    [2025-04-16 10:37:12,077] - config.logger - SQLite error: table users already exists
dispatcher.py:527 #INFO     [2025-04-16 10:37:12,316] - aiogram.dispatcher - Start polling
dispatcher.py:341 #INFO     [2025-04-16 10:37:12,451] - aiogram.dispatcher - Run polling for bot @justdotrobot id=6652950296 - '.'
subscription.py:30 #INFO     [2025-04-16 10:37:16,828] - config.logger - USER: 1856563190, Azizbek Qodirov
subscription.py:50 #WARNING  [2025-04-16 10:37:17,505] - config.logger - Error checking channel -1001500104999: Telegram server says - Bad Request: chat not found
dispatcher.py:172 #INFO     [2025-04-16 10:37:17,744] - aiogram.event - Update id=661102364 is not handled. Duration 917 ms by bot id=6652950296
dispatcher.py:315 #ERROR    [2025-04-16 10:37:17,744] - aiogram.event - Cause exception while process update id=661102364 by bot id=6652950296
TelegramBadRequest: Telegram server says - Bad Request: wrong file identifier/HTTP URL specified
Traceback (most recent call last):
  File "/media/gopher/workspace/lin/py-projects/anonbot/venv/lib/python3.13/site-packages/aiogram/dispatcher/dispatcher.py", line 309, in _process_update
    response = await self.feed_update(bot, update, **kwargs)
               ^^^^^^^^^^^^^^^^^^^^^^^^^^^^^^^^^^^^^^^^^^^^^
  File "/media/gopher/workspace/lin/py-projects/anonbot/venv/lib/python3.13/site-packages/aiogram/dispatcher/dispatcher.py", line 158, in feed_update
    response = await self.update.wrap_outer_middleware(
               ^^^^^^^^^^^^^^^^^^^^^^^^^^^^^^^^^^^^^^^^
    ...<7 lines>...
    )
    ^
  File "/media/gopher/workspace/lin/py-projects/anonbot/venv/lib/python3.13/site-packages/aiogram/dispatcher/middlewares/error.py", line 25, in __call__
    return await handler(event, data)
           ^^^^^^^^^^^^^^^^^^^^^^^^^^
  File "/media/gopher/workspace/lin/py-projects/anonbot/venv/lib/python3.13/site-packages/aiogram/dispatcher/middlewares/user_context.py", line 56, in __call__
    return await handler(event, data)
           ^^^^^^^^^^^^^^^^^^^^^^^^^^
  File "/media/gopher/workspace/lin/py-projects/anonbot/venv/lib/python3.13/site-packages/aiogram/fsm/middleware.py", line 42, in __call__
    return await handler(event, data)
           ^^^^^^^^^^^^^^^^^^^^^^^^^^
  File "/media/gopher/workspace/lin/py-projects/anonbot/venv/lib/python3.13/site-packages/aiogram/dispatcher/event/telegram.py", line 121, in trigger
    return await wrapped_inner(event, kwargs)
           ^^^^^^^^^^^^^^^^^^^^^^^^^^^^^^^^^^
  File "/media/gopher/workspace/lin/py-projects/anonbot/venv/lib/python3.13/site-packages/aiogram/dispatcher/event/handler.py", line 43, in call
    return await wrapped()
           ^^^^^^^^^^^^^^^
  File "/media/gopher/workspace/lin/py-projects/anonbot/venv/lib/python3.13/site-packages/aiogram/dispatcher/dispatcher.py", line 276, in _listen_update
    return await self.propagate_event(update_type=update_type, event=event, **kwargs)
           ^^^^^^^^^^^^^^^^^^^^^^^^^^^^^^^^^^^^^^^^^^^^^^^^^^^^^^^^^^^^^^^^^^^^^^^^^^
  File "/media/gopher/workspace/lin/py-projects/anonbot/venv/lib/python3.13/site-packages/aiogram/dispatcher/router.py", line 146, in propagate_event
    return await observer.wrap_outer_middleware(_wrapped, event=event, data=kwargs)
           ^^^^^^^^^^^^^^^^^^^^^^^^^^^^^^^^^^^^^^^^^^^^^^^^^^^^^^^^^^^^^^^^^^^^^^^^
  File "/media/gopher/workspace/lin/py-projects/anonbot/venv/lib/python3.13/site-packages/aiogram/dispatcher/router.py", line 141, in _wrapped
    return await self._propagate_event(
           ^^^^^^^^^^^^^^^^^^^^^^^^^^^^
        observer=observer, update_type=update_type, event=telegram_event, **data
        ^^^^^^^^^^^^^^^^^^^^^^^^^^^^^^^^^^^^^^^^^^^^^^^^^^^^^^^^^^^^^^^^^^^^^^^^
    )
    ^
  File "/media/gopher/workspace/lin/py-projects/anonbot/venv/lib/python3.13/site-packages/aiogram/dispatcher/router.py", line 174, in _propagate_event
    response = await router.propagate_event(update_type=update_type, event=event, **kwargs)
               ^^^^^^^^^^^^^^^^^^^^^^^^^^^^^^^^^^^^^^^^^^^^^^^^^^^^^^^^^^^^^^^^^^^^^^^^^^^^
  File "/media/gopher/workspace/lin/py-projects/anonbot/venv/lib/python3.13/site-packages/aiogram/dispatcher/router.py", line 146, in propagate_event
    return await observer.wrap_outer_middleware(_wrapped, event=event, data=kwargs)
           ^^^^^^^^^^^^^^^^^^^^^^^^^^^^^^^^^^^^^^^^^^^^^^^^^^^^^^^^^^^^^^^^^^^^^^^^
  File "/media/gopher/workspace/lin/py-projects/anonbot/venv/lib/python3.13/site-packages/aiogram/dispatcher/router.py", line 141, in _wrapped
    return await self._propagate_event(
           ^^^^^^^^^^^^^^^^^^^^^^^^^^^^
        observer=observer, update_type=update_type, event=telegram_event, **data
        ^^^^^^^^^^^^^^^^^^^^^^^^^^^^^^^^^^^^^^^^^^^^^^^^^^^^^^^^^^^^^^^^^^^^^^^^
    )
    ^
  File "/media/gopher/workspace/lin/py-projects/anonbot/venv/lib/python3.13/site-packages/aiogram/dispatcher/router.py", line 166, in _propagate_event
    response = await observer.trigger(event, **kwargs)
               ^^^^^^^^^^^^^^^^^^^^^^^^^^^^^^^^^^^^^^^
  File "/media/gopher/workspace/lin/py-projects/anonbot/venv/lib/python3.13/site-packages/aiogram/dispatcher/event/telegram.py", line 121, in trigger
    return await wrapped_inner(event, kwargs)
           ^^^^^^^^^^^^^^^^^^^^^^^^^^^^^^^^^^
  File "/media/gopher/workspace/lin/py-projects/free-course4/src/middleware/subscription.py", line 93, in __call__
    return await handler(event, data)
           ^^^^^^^^^^^^^^^^^^^^^^^^^^
  File "/media/gopher/workspace/lin/py-projects/anonbot/venv/lib/python3.13/site-packages/aiogram/dispatcher/event/handler.py", line 43, in call
    return await wrapped()
           ^^^^^^^^^^^^^^^
  File "/media/gopher/workspace/lin/py-projects/free-course4/src/handlers/start.py", line 59, in bot_start
    await message.answer_photo(photo=msg.photo_id, caption=msg.text_1, parse_mode=ParseMode.HTML)
  File "/media/gopher/workspace/lin/py-projects/anonbot/venv/lib/python3.13/site-packages/aiogram/methods/base.py", line 84, in emit
    return await bot(self)
           ^^^^^^^^^^^^^^^
  File "/media/gopher/workspace/lin/py-projects/anonbot/venv/lib/python3.13/site-packages/aiogram/client/bot.py", line 453, in __call__
    return await self.session(self, method, timeout=request_timeout)
           ^^^^^^^^^^^^^^^^^^^^^^^^^^^^^^^^^^^^^^^^^^^^^^^^^^^^^^^^^
  File "/media/gopher/workspace/lin/py-projects/anonbot/venv/lib/python3.13/site-packages/aiogram/client/session/base.py", line 254, in __call__
    return cast(TelegramType, await middleware(bot, method))
                              ^^^^^^^^^^^^^^^^^^^^^^^^^^^^^
  File "/media/gopher/workspace/lin/py-projects/anonbot/venv/lib/python3.13/site-packages/aiogram/client/session/aiohttp.py", line 185, in make_request
    response = self.check_response(
        bot=bot, method=method, status_code=resp.status, content=raw_result
    )
  File "/media/gopher/workspace/lin/py-projects/anonbot/venv/lib/python3.13/site-packages/aiogram/client/session/base.py", line 120, in check_response
    raise TelegramBadRequest(method=method, message=description)
aiogram.exceptions.TelegramBadRequest: Telegram server says - Bad Request: wrong file identifier/HTTP URL specified
subscription.py:30 #INFO     [2025-04-16 10:37:43,293] - config.logger - USER: 1856563190, Azizbek Qodirov
subscription.py:91 #CRITICAL [2025-04-16 10:37:43,294] - config.logger - Error in SubscriptionMiddleware: 'NoneType' object has no attribute 'startswith'
start.py:65 #INFO     [2025-04-16 10:37:43,295] - config.logger - Photo ID: AgACAgIAAxkBAAIOo2f_QidqxoDMnvvN5WSkzfzfVhbHAAJq7TEbh__4S83Tm0f1YjPnAQADAgADeAADNgQ
dispatcher.py:172 #INFO     [2025-04-16 10:37:43,295] - aiogram.event - Update id=661102365 is handled. Duration 3 ms by bot id=6652950296
dispatcher.py:455 #WARNING  [2025-04-16 10:37:54,129] - aiogram.dispatcher - Received SIGINT signal
dispatcher.py:359 #INFO     [2025-04-16 10:37:54,130] - aiogram.dispatcher - Polling stopped for bot @justdotrobot id=6652950296 - '.'
dispatcher.py:554 #INFO     [2025-04-16 10:37:54,131] - aiogram.dispatcher - Polling stopped
client.py:22 #INFO     [2025-04-16 10:37:54,383] - config.logger - Connection to SQLite closed!
main.py:10 #INFO     [2025-04-16 10:42:03,137] - config.logger - Starting bot
client.py:15 #INFO     [2025-04-16 10:42:09,661] - config.logger - Successfully connected to the SQLite database!
client.py:45 #ERROR    [2025-04-16 10:42:09,661] - config.logger - SQLite error: table users already exists
dispatcher.py:527 #INFO     [2025-04-16 10:42:09,920] - aiogram.dispatcher - Start polling
dispatcher.py:341 #INFO     [2025-04-16 10:42:10,072] - aiogram.dispatcher - Run polling for bot @justdotrobot id=6652950296 - '.'
subscription.py:30 #INFO     [2025-04-16 10:42:11,559] - config.logger - USER: 1856563190, Azizbek Qodirov
subscription.py:50 #WARNING  [2025-04-16 10:42:12,020] - config.logger - Error checking channel -1001500104999: Telegram server says - Bad Request: chat not found
dispatcher.py:172 #INFO     [2025-04-16 10:42:12,465] - aiogram.event - Update id=661102366 is handled. Duration 907 ms by bot id=6652950296
dispatcher.py:455 #WARNING  [2025-04-16 10:56:44,231] - aiogram.dispatcher - Received SIGINT signal
dispatcher.py:359 #INFO     [2025-04-16 10:56:44,233] - aiogram.dispatcher - Polling stopped for bot @justdotrobot id=6652950296 - '.'
dispatcher.py:554 #INFO     [2025-04-16 10:56:44,234] - aiogram.dispatcher - Polling stopped
client.py:22 #INFO     [2025-04-16 10:56:44,486] - config.logger - Connection to SQLite closed!
main.py:10 #INFO     [2025-04-16 10:56:47,942] - config.logger - Starting bot
client.py:15 #INFO     [2025-04-16 10:56:48,709] - config.logger - Successfully connected to the SQLite database!
client.py:45 #ERROR    [2025-04-16 10:56:48,710] - config.logger - SQLite error: table users already exists
dispatcher.py:527 #INFO     [2025-04-16 10:56:48,954] - aiogram.dispatcher - Start polling
dispatcher.py:341 #INFO     [2025-04-16 10:56:49,157] - aiogram.dispatcher - Run polling for bot @justdotrobot id=6652950296 - '.'
subscription.py:30 #INFO     [2025-04-16 10:56:51,062] - config.logger - USER: 1856563190, Azizbek Qodirov
subscription.py:50 #WARNING  [2025-04-16 10:56:51,944] - config.logger - Error checking channel -1001500104999: Telegram server says - Bad Request: chat not found
dispatcher.py:172 #INFO     [2025-04-16 10:56:52,516] - aiogram.event - Update id=661102367 is handled. Duration 1455 ms by bot id=6652950296
dispatcher.py:219 #ERROR    [2025-04-16 12:12:20,251] - aiogram.dispatcher - Failed to fetch updates - TelegramNetworkError: HTTP Client says - Request timeout error
dispatcher.py:221 #WARNING  [2025-04-16 12:12:20,252] - aiogram.dispatcher - Sleep for 1.000000 seconds and try again... (tryings = 0, bot id = 6652950296)
dispatcher.py:233 #INFO     [2025-04-16 12:12:32,513] - aiogram.dispatcher - Connection established (tryings = 1, bot id = 6652950296)
main.py:10 #INFO     [2025-04-16 23:50:43,260] - config.logger - Starting bot
base_events.py:1865 #ERROR    [2025-04-16 23:50:58,312] - asyncio - Unclosed client session
client_session: <aiohttp.client.ClientSession object at 0x7fbb2e07fcb0>
base_events.py:1865 #ERROR    [2025-04-16 23:50:58,313] - asyncio - Unclosed connector
connections: ['deque([(<aiohttp.client_proto.ResponseHandler object at 0x7fbb2dec29f0>, 3939.502041324)])']
connector: <aiohttp.connector.TCPConnector object at 0x7fbb2e07f8c0>
main.py:10 #INFO     [2025-04-16 23:51:40,925] - config.logger - Starting bot
telegram.py:19 #WARNING  [2025-04-16 23:51:41,608] - config.logger - Can't send start message to DEVID: 1856563190 Err:Telegram server says - Bad Request: chat not found
client.py:15 #INFO     [2025-04-16 23:51:41,609] - config.logger - Successfully connected to the SQLite database!
client.py:45 #ERROR    [2025-04-16 23:51:41,610] - config.logger - SQLite error: table users already exists
dispatcher.py:527 #INFO     [2025-04-16 23:51:41,738] - aiogram.dispatcher - Start polling
dispatcher.py:341 #INFO     [2025-04-16 23:51:41,876] - aiogram.dispatcher - Run polling for bot @IELTS_reading_booster_bot id=7692328299 - 'IELTS Reading Booster'
subscription.py:30 #INFO     [2025-04-16 23:53:23,464] - config.logger - USER: 1856563190, Azizbek Qodirov
subscription.py:50 #WARNING  [2025-04-16 23:53:23,871] - config.logger - Error checking channel -1001500104999: Telegram server says - Bad Request: chat not found
dispatcher.py:172 #INFO     [2025-04-16 23:53:24,030] - aiogram.event - Update id=87796202 is not handled. Duration 567 ms by bot id=7692328299
dispatcher.py:315 #ERROR    [2025-04-16 23:53:24,031] - aiogram.event - Cause exception while process update id=87796202 by bot id=7692328299
TelegramBadRequest: Telegram server says - Bad Request: wrong file identifier/HTTP URL specified
Traceback (most recent call last):
  File "/media/gopher/workspace/lin/py-projects/anonbot/venv/lib/python3.13/site-packages/aiogram/dispatcher/dispatcher.py", line 309, in _process_update
    response = await self.feed_update(bot, update, **kwargs)
               ^^^^^^^^^^^^^^^^^^^^^^^^^^^^^^^^^^^^^^^^^^^^^
  File "/media/gopher/workspace/lin/py-projects/anonbot/venv/lib/python3.13/site-packages/aiogram/dispatcher/dispatcher.py", line 158, in feed_update
    response = await self.update.wrap_outer_middleware(
               ^^^^^^^^^^^^^^^^^^^^^^^^^^^^^^^^^^^^^^^^
    ...<7 lines>...
    )
    ^
  File "/media/gopher/workspace/lin/py-projects/anonbot/venv/lib/python3.13/site-packages/aiogram/dispatcher/middlewares/error.py", line 25, in __call__
    return await handler(event, data)
           ^^^^^^^^^^^^^^^^^^^^^^^^^^
  File "/media/gopher/workspace/lin/py-projects/anonbot/venv/lib/python3.13/site-packages/aiogram/dispatcher/middlewares/user_context.py", line 56, in __call__
    return await handler(event, data)
           ^^^^^^^^^^^^^^^^^^^^^^^^^^
  File "/media/gopher/workspace/lin/py-projects/anonbot/venv/lib/python3.13/site-packages/aiogram/fsm/middleware.py", line 42, in __call__
    return await handler(event, data)
           ^^^^^^^^^^^^^^^^^^^^^^^^^^
  File "/media/gopher/workspace/lin/py-projects/anonbot/venv/lib/python3.13/site-packages/aiogram/dispatcher/event/telegram.py", line 121, in trigger
    return await wrapped_inner(event, kwargs)
           ^^^^^^^^^^^^^^^^^^^^^^^^^^^^^^^^^^
  File "/media/gopher/workspace/lin/py-projects/anonbot/venv/lib/python3.13/site-packages/aiogram/dispatcher/event/handler.py", line 43, in call
    return await wrapped()
           ^^^^^^^^^^^^^^^
  File "/media/gopher/workspace/lin/py-projects/anonbot/venv/lib/python3.13/site-packages/aiogram/dispatcher/dispatcher.py", line 276, in _listen_update
    return await self.propagate_event(update_type=update_type, event=event, **kwargs)
           ^^^^^^^^^^^^^^^^^^^^^^^^^^^^^^^^^^^^^^^^^^^^^^^^^^^^^^^^^^^^^^^^^^^^^^^^^^
  File "/media/gopher/workspace/lin/py-projects/anonbot/venv/lib/python3.13/site-packages/aiogram/dispatcher/router.py", line 146, in propagate_event
    return await observer.wrap_outer_middleware(_wrapped, event=event, data=kwargs)
           ^^^^^^^^^^^^^^^^^^^^^^^^^^^^^^^^^^^^^^^^^^^^^^^^^^^^^^^^^^^^^^^^^^^^^^^^
  File "/media/gopher/workspace/lin/py-projects/anonbot/venv/lib/python3.13/site-packages/aiogram/dispatcher/router.py", line 141, in _wrapped
    return await self._propagate_event(
           ^^^^^^^^^^^^^^^^^^^^^^^^^^^^
        observer=observer, update_type=update_type, event=telegram_event, **data
        ^^^^^^^^^^^^^^^^^^^^^^^^^^^^^^^^^^^^^^^^^^^^^^^^^^^^^^^^^^^^^^^^^^^^^^^^
    )
    ^
  File "/media/gopher/workspace/lin/py-projects/anonbot/venv/lib/python3.13/site-packages/aiogram/dispatcher/router.py", line 174, in _propagate_event
    response = await router.propagate_event(update_type=update_type, event=event, **kwargs)
               ^^^^^^^^^^^^^^^^^^^^^^^^^^^^^^^^^^^^^^^^^^^^^^^^^^^^^^^^^^^^^^^^^^^^^^^^^^^^
  File "/media/gopher/workspace/lin/py-projects/anonbot/venv/lib/python3.13/site-packages/aiogram/dispatcher/router.py", line 146, in propagate_event
    return await observer.wrap_outer_middleware(_wrapped, event=event, data=kwargs)
           ^^^^^^^^^^^^^^^^^^^^^^^^^^^^^^^^^^^^^^^^^^^^^^^^^^^^^^^^^^^^^^^^^^^^^^^^
  File "/media/gopher/workspace/lin/py-projects/anonbot/venv/lib/python3.13/site-packages/aiogram/dispatcher/router.py", line 141, in _wrapped
    return await self._propagate_event(
           ^^^^^^^^^^^^^^^^^^^^^^^^^^^^
        observer=observer, update_type=update_type, event=telegram_event, **data
        ^^^^^^^^^^^^^^^^^^^^^^^^^^^^^^^^^^^^^^^^^^^^^^^^^^^^^^^^^^^^^^^^^^^^^^^^
    )
    ^
  File "/media/gopher/workspace/lin/py-projects/anonbot/venv/lib/python3.13/site-packages/aiogram/dispatcher/router.py", line 166, in _propagate_event
    response = await observer.trigger(event, **kwargs)
               ^^^^^^^^^^^^^^^^^^^^^^^^^^^^^^^^^^^^^^^
  File "/media/gopher/workspace/lin/py-projects/anonbot/venv/lib/python3.13/site-packages/aiogram/dispatcher/event/telegram.py", line 121, in trigger
    return await wrapped_inner(event, kwargs)
           ^^^^^^^^^^^^^^^^^^^^^^^^^^^^^^^^^^
  File "/media/gopher/workspace/lin/py-projects/free-course4/src/middleware/subscription.py", line 93, in __call__
    return await handler(event, data)
           ^^^^^^^^^^^^^^^^^^^^^^^^^^
  File "/media/gopher/workspace/lin/py-projects/anonbot/venv/lib/python3.13/site-packages/aiogram/dispatcher/event/handler.py", line 43, in call
    return await wrapped()
           ^^^^^^^^^^^^^^^
  File "/media/gopher/workspace/lin/py-projects/free-course4/src/handlers/start.py", line 59, in bot_start
    await message.answer_photo(photo=msg.photo_id, caption=msg.text_1, parse_mode=ParseMode.HTML)
  File "/media/gopher/workspace/lin/py-projects/anonbot/venv/lib/python3.13/site-packages/aiogram/methods/base.py", line 84, in emit
    return await bot(self)
           ^^^^^^^^^^^^^^^
  File "/media/gopher/workspace/lin/py-projects/anonbot/venv/lib/python3.13/site-packages/aiogram/client/bot.py", line 453, in __call__
    return await self.session(self, method, timeout=request_timeout)
           ^^^^^^^^^^^^^^^^^^^^^^^^^^^^^^^^^^^^^^^^^^^^^^^^^^^^^^^^^
  File "/media/gopher/workspace/lin/py-projects/anonbot/venv/lib/python3.13/site-packages/aiogram/client/session/base.py", line 254, in __call__
    return cast(TelegramType, await middleware(bot, method))
                              ^^^^^^^^^^^^^^^^^^^^^^^^^^^^^
  File "/media/gopher/workspace/lin/py-projects/anonbot/venv/lib/python3.13/site-packages/aiogram/client/session/aiohttp.py", line 185, in make_request
    response = self.check_response(
        bot=bot, method=method, status_code=resp.status, content=raw_result
    )
  File "/media/gopher/workspace/lin/py-projects/anonbot/venv/lib/python3.13/site-packages/aiogram/client/session/base.py", line 120, in check_response
    raise TelegramBadRequest(method=method, message=description)
aiogram.exceptions.TelegramBadRequest: Telegram server says - Bad Request: wrong file identifier/HTTP URL specified
subscription.py:30 #INFO     [2025-04-16 23:53:37,507] - config.logger - USER: 1856563190, Azizbek Qodirov
subscription.py:91 #CRITICAL [2025-04-16 23:53:37,508] - config.logger - Error in SubscriptionMiddleware: 'NoneType' object has no attribute 'startswith'
start.py:65 #INFO     [2025-04-16 23:53:37,508] - config.logger - Photo ID: AgACAgIAAxkBAAMCZ__8saV2uiwlKhe_qiBFiEwRHdQAAqHzMRtnbAFIDbex5IPPvI8BAAMCAAN4AAM2BA
dispatcher.py:172 #INFO     [2025-04-16 23:53:37,508] - aiogram.event - Update id=87796203 is handled. Duration 3 ms by bot id=7692328299
dispatcher.py:455 #WARNING  [2025-04-16 23:53:48,265] - aiogram.dispatcher - Received SIGINT signal
dispatcher.py:359 #INFO     [2025-04-16 23:53:48,266] - aiogram.dispatcher - Polling stopped for bot @IELTS_reading_booster_bot id=7692328299 - 'IELTS Reading Booster'
dispatcher.py:554 #INFO     [2025-04-16 23:53:48,266] - aiogram.dispatcher - Polling stopped
client.py:22 #INFO     [2025-04-16 23:53:48,518] - config.logger - Connection to SQLite closed!
main.py:10 #INFO     [2025-04-16 23:53:51,668] - config.logger - Starting bot
client.py:15 #INFO     [2025-04-16 23:53:52,239] - config.logger - Successfully connected to the SQLite database!
client.py:45 #ERROR    [2025-04-16 23:53:52,240] - config.logger - SQLite error: table users already exists
dispatcher.py:527 #INFO     [2025-04-16 23:53:52,390] - aiogram.dispatcher - Start polling
dispatcher.py:341 #INFO     [2025-04-16 23:53:52,517] - aiogram.dispatcher - Run polling for bot @IELTS_reading_booster_bot id=7692328299 - 'IELTS Reading Booster'
subscription.py:30 #INFO     [2025-04-16 23:53:53,525] - config.logger - USER: 1856563190, Azizbek Qodirov
subscription.py:50 #WARNING  [2025-04-16 23:53:53,911] - config.logger - Error checking channel -1001500104999: Telegram server says - Bad Request: chat not found
dispatcher.py:172 #INFO     [2025-04-16 23:53:54,279] - aiogram.event - Update id=87796204 is handled. Duration 755 ms by bot id=7692328299
subscription.py:30 #INFO     [2025-04-16 23:54:32,618] - config.logger - USER: 1856563190, Azizbek Qodirov
subscription.py:50 #WARNING  [2025-04-16 23:54:32,855] - config.logger - Error checking channel -1001500104999: Telegram server says - Bad Request: chat not found
dispatcher.py:172 #INFO     [2025-04-16 23:54:33,317] - aiogram.event - Update id=87796205 is handled. Duration 701 ms by bot id=7692328299
subscription.py:30 #INFO     [2025-04-16 23:54:42,633] - config.logger - USER: 1856563190, Azizbek Qodirov
subscription.py:50 #WARNING  [2025-04-16 23:54:42,768] - config.logger - Error checking channel -1001500104999: Telegram server says - Bad Request: chat not found
dispatcher.py:172 #INFO     [2025-04-16 23:54:42,928] - aiogram.event - Update id=87796206 is handled. Duration 296 ms by bot id=7692328299
dispatcher.py:172 #INFO     [2025-04-16 23:54:50,040] - aiogram.event - Update id=87796207 is handled. Duration 304 ms by bot id=7692328299
subscription.py:30 #INFO     [2025-04-16 23:55:12,871] - config.logger - USER: 1856563190, Azizbek Qodirov
subscription.py:50 #WARNING  [2025-04-16 23:55:13,019] - config.logger - Error checking channel -1001500104999: Telegram server says - Bad Request: chat not found
dispatcher.py:172 #INFO     [2025-04-16 23:55:13,205] - aiogram.event - Update id=87796208 is handled. Duration 334 ms by bot id=7692328299
subscription.py:30 #INFO     [2025-04-16 23:55:14,246] - config.logger - USER: 1856563190, Azizbek Qodirov
subscription.py:50 #WARNING  [2025-04-16 23:55:14,393] - config.logger - Error checking channel -1001500104999: Telegram server says - Bad Request: chat not found
dispatcher.py:172 #INFO     [2025-04-16 23:55:14,540] - aiogram.event - Update id=87796209 is handled. Duration 295 ms by bot id=7692328299
subscription.py:30 #INFO     [2025-04-16 23:55:23,270] - config.logger - USER: 1856563190, Azizbek Qodirov
subscription.py:50 #WARNING  [2025-04-16 23:55:23,419] - config.logger - Error checking channel -1001500104999: Telegram server says - Bad Request: chat not found
dispatcher.py:172 #INFO     [2025-04-16 23:55:23,576] - aiogram.event - Update id=87796210 is handled. Duration 306 ms by bot id=7692328299
subscription.py:30 #INFO     [2025-04-16 23:55:26,889] - config.logger - USER: 1856563190, Azizbek Qodirov
subscription.py:50 #WARNING  [2025-04-16 23:55:27,032] - config.logger - Error checking channel -1001500104999: Telegram server says - Bad Request: chat not found
dispatcher.py:172 #INFO     [2025-04-16 23:55:27,183] - aiogram.event - Update id=87796211 is handled. Duration 294 ms by bot id=7692328299
subscription.py:30 #INFO     [2025-04-16 23:55:28,698] - config.logger - USER: 1856563190, Azizbek Qodirov
subscription.py:50 #WARNING  [2025-04-16 23:55:28,844] - config.logger - Error checking channel -1001500104999: Telegram server says - Bad Request: chat not found
dispatcher.py:172 #INFO     [2025-04-16 23:55:29,183] - aiogram.event - Update id=87796212 is handled. Duration 486 ms by bot id=7692328299
subscription.py:30 #INFO     [2025-04-16 23:55:52,554] - config.logger - USER: 1856563190, Azizbek Qodirov
subscription.py:50 #WARNING  [2025-04-16 23:55:52,691] - config.logger - Error checking channel -1001500104999: Telegram server says - Bad Request: chat not found
dispatcher.py:172 #INFO     [2025-04-16 23:55:52,849] - aiogram.event - Update id=87796213 is handled. Duration 297 ms by bot id=7692328299
dispatcher.py:455 #WARNING  [2025-04-16 23:57:23,622] - aiogram.dispatcher - Received SIGINT signal
dispatcher.py:359 #INFO     [2025-04-16 23:57:23,623] - aiogram.dispatcher - Polling stopped for bot @IELTS_reading_booster_bot id=7692328299 - 'IELTS Reading Booster'
dispatcher.py:554 #INFO     [2025-04-16 23:57:23,624] - aiogram.dispatcher - Polling stopped
client.py:22 #INFO     [2025-04-16 23:57:23,877] - config.logger - Connection to SQLite closed!
